[32m2024-12-10 14:54:06 +0100[0m - dagster - [34mDEBUG[0m - __ASSET_JOB - f816c2b1-0d0a-4661-9252-05c783a54cef - 281549 - LOGS_CAPTURED - Started capturing logs in process (pid: 281549).
[32m2024-12-10 14:54:06 +0100[0m - dagster - [34mDEBUG[0m - __ASSET_JOB - f816c2b1-0d0a-4661-9252-05c783a54cef - 281549 - daily_bike_rental_demand - STEP_START - Started execution of step "daily_bike_rental_demand".
[32m2024-12-10 14:54:06 +0100[0m - dagster - [34mERROR[0m - [31m__ASSET_JOB - f816c2b1-0d0a-4661-9252-05c783a54cef - 281549 - daily_bike_rental_demand - STEP_FAILURE - Execution of step "daily_bike_rental_demand" failed.

dagster._core.errors.DagsterExecutionStepExecutionError: Error occurred while executing op "daily_bike_rental_demand"::

pydantic_core._pydantic_core.ValidationError: 1 validation error for DataLoader
data_directory
  Input should be a valid string [type=string_type, input_value=None, input_type=NoneType]
    For further information visit https://errors.pydantic.dev/2.10/v/string_type

Stack Trace:
  File "/home/kai/miniconda3/envs/bike-share/lib/python3.12/site-packages/dagster/_core/execution/plan/utils.py", line 54, in op_execution_error_boundary
    yield
  File "/home/kai/miniconda3/envs/bike-share/lib/python3.12/site-packages/dagster/_utils/__init__.py", line 490, in iterate_with_context
    next_output = next(iterator)
                  ^^^^^^^^^^^^^^
  File "/home/kai/miniconda3/envs/bike-share/lib/python3.12/site-packages/dagster/_core/execution/plan/compute_generator.py", line 140, in _coerce_op_compute_fn_to_iterator
    result = invoke_compute_fn(
             ^^^^^^^^^^^^^^^^^^
  File "/home/kai/miniconda3/envs/bike-share/lib/python3.12/site-packages/dagster/_core/execution/plan/compute_generator.py", line 128, in invoke_compute_fn
    return fn(context, **args_to_pass) if context_arg_provided else fn(**args_to_pass)
                                                                    ^^^^^^^^^^^^^^^^^^
  File "/home/kai/Git/twai_mlops_assignment2-main/src/bike_share/assets/daily_bike_rental_demand.py", line 11, in daily_bike_rental_demand
    return DataLoader().load()
           ^^^^^^^^^^^^
  File "/home/kai/miniconda3/envs/bike-share/lib/python3.12/site-packages/dagster/_config/pythonic_config/resource.py", line 230, in __init__
    super().__init__(**data_without_resources, **resource_pointers)
  File "/home/kai/miniconda3/envs/bike-share/lib/python3.12/site-packages/dagster/_config/pythonic_config/config.py", line 250, in __init__
    super().__init__(**modified_data_by_config_key)
  File "/home/kai/miniconda3/envs/bike-share/lib/python3.12/site-packages/pydantic/main.py", line 214, in __init__
    validated_self = self.__pydantic_validator__.validate_python(data, self_instance=self)
                     ^^^^^^^^^^^^^^^^^^^^^^^^^^^^^^^^^^^^^^^^^^^^^^^^^^^^^^^^^^^^^^^^^^^^^
[0m
